<!-- =================================================
    Copyright 2026 NeuMove Laboratory, Northeastern University
    Model   :: Open Source Leg - Knee + Ankle (Transfemoral)
    Author  :: Calder Robbins (robbins.cal@northeastern.edu)
    License :: Apache License, Version 2.0
====================================================== -->
<mujoco model="OSL_KneeAnkle">
    <compiler angle="radian"/>

    <default class="main">
        <default class="coll">
            <geom type="capsule" group="4" contype="1" conaffinity="0" condim="3" rgba="0.8 0.7 .5 1" margin="0.001"/>
        </default>
        <default class="myo_leg_touch">
            <site type="box" group="3" rgba="0.8 0.2 .2 .4"/>
        </default>
    </default>

    <asset>
        <!-- Prosthetic components -->
        <mesh file="mesh/osl_generic_socket_femur.stl" name="osl_generic_socket"/>
        <mesh file="mesh/osl_proximal_adapter_v2.stl" name="osl_proximal_adapter"/>
        <mesh file="mesh/osl_knee_v2.stl" name="osl_knee_assembly"/>
        <mesh file="mesh/osl_ankle_v2.stl" name="osl_ankle_assembly_geom_1_osl_ankle_v2"/>
        <mesh file="mesh/osl_custom_foot_v2.stl" name="osl_foot_assembly_geom_1_osl_custom_foot_v2"/>
        <!-- Replacement mesh for the residual femur -->
        <mesh file="mesh/osl_femur_trans_r.stl" name="osl_femur_trans_r"/>
    </asset>

    <worldbody>
        <body name="osl_generic_socket" pos="-0.0045 -0.295 0.017">
            <inertial pos="0 0.101169 0" quat="0.707107 0.707107 0 0" mass="0.849991" diaginertia="0.0039776 0.0039776 0.0027545"/>
            <geom name="osl_generic_socket" type="mesh" rgba="0.2 0.2 0.2 0.35" mesh="osl_generic_socket" condim="3" contype="1"/>

            <body name="osl_femoral_pylon" pos="0 -0.02829 0">
                <site name="r_socket_load_force" type="box" pos="0 0.105 0.005" size="0.02 0.003 0.02" euler="0 0 0" group="3" rgba="0.8 0.2 .2 .4"/>
                <inertial pos="0 0 0" mass="0.0220583" diaginertia="0.001 0.001 0.001"/>
                <geom name="osl_femoral_pylon_geom_1" type="cylinder" size="0.012 0.028394449243889931" quat="0.707035 0.707179 0 0" rgba="0.2 0.2 0.2 1" condim="3" contype="1"/>

                <body name="osl_proximal_adapter" pos="0 -0.08441 0">
                    <inertial pos="0 0.02176 0" quat="0.996071 0.0885602 0 0" mass="0.167" diaginertia="0.001 0.001 0.001"/>
                    <geom name="osl_proximal_adapter_geom_1" type="mesh" rgba="0.2 0.2 0.2 1" mesh="osl_proximal_adapter" condim="3" contype="1"/>
                </body>
                <body name="osl_knee_assembly" pos="0 -0.08441 0">
                    <inertial pos="0.00381 -0.05901 0.00918" quat="0.659658 0.705162 0.180917 -0.186728" mass="2.2455" diaginertia="0.00930494 0.00919978 0.00355928"/>
                    <joint name="osl_knee_angle_r" pos="0 0 0" axis="0 0 -1" range="0 2.0944"/>
                    <geom name="osl_knee_assembly_geom_1" type="mesh" rgba="0.8 0.8 0.8 1" mesh="osl_knee_assembly" condim="3" contype="1"/>

                    <body name="osl_tibial_pylon" pos="0 -0.22 0.006">
                        <inertial pos="0 0 0" mass="0.0629248" diaginertia="0.001 0.001 0.001"/>
                        <geom name="osl_tibial_pylon_geom_1" type="cylinder" size="0.012 0.065" quat="0.707035 0.707179 0 0" rgba="0.2 0.2 0.2 1" condim="3" contype="1"/>

                        <body name="osl_ankle_assembly" pos="0 -0.1561 -0.006">
                            <inertial pos="-0.00665 0.04539 0.00924" quat="0.612323 0.440299 -0.442253 0.485396" mass="1.739" diaginertia="0.00535042 0.00492977 0.0030318"/>
                            <geom name="osl_ankle_assembly_geom_1" type="mesh" rgba="0.8 0.8 0.8 1" mesh="osl_ankle_assembly_geom_1_osl_ankle_v2" condim="3" contype="1"/>
                            <site name="r_osl_load_force" type="box" pos="0 0.105 0.005" size="0.02 0.003 0.02" euler="0 0 0" group="3" rgba="0.8 0.2 .2 .4"/>

                            <body name="osl_foot_assembly" pos="0 0 0">
                                <inertial pos="0.064562 -0.048401 0.004732" quat="0.482413 0.245831 0.66522 0.514127" mass="0.291" diaginertia="0.00145886 0.00139898 0.001"/>
                                <joint name="osl_ankle_angle_r" pos="0 0 0" axis="0 0 1" range="-0.5236 0.5236"/>
                                <geom name="osl_foot_assembly_geom_1" type="mesh" rgba="0.2 0.2 0.2 1" mesh="osl_foot_assembly_geom_1_osl_custom_foot_v2"/>

                                <geom name="osl_foot_col1" size=".012" class="coll" fromto="0.19 -0.05 0.007 -0.03 -0.05 0.007" group="5"/>
                                <geom name="osl_foot_col2" size=".012" class="coll" fromto="0.182 -0.05 0.028 -0.03 -0.05 0.028" group="5"/>
                                <geom name="osl_foot_col3" size=".012" class="coll" fromto="0.182 -0.05 -0.015 -0.03 -0.05 -0.015" group="5"/>

                                <site name="r_foot_touch" type="box" pos="0.025 -0.04 0.0" size=".05 .03 .05" euler="0 0 0" class="myo_leg_touch"/>
                                <site name="r_toes_touch" type="box" pos="0.215 -0.04 -0.005" size=".075 .03 .06" euler="0 0 0" class="myo_leg_touch"/>
                            </body>
                        </body>
                    </body>
                </body>
            </body>
        </body>
    </worldbody>
</mujoco>
